<mujoco model="demo1_go2_real">
  <!-- demo1_go2_real: Menagerie Go2 (calf-tip centered feet) + demo1 world (12×8m).
       Replaces demo1_go2.xml (broken stripped-Go2W: foot sphere offset ±4 cm sideways
       from calf centerline broke CHAMP gait). Menagerie body has foot collision at
       pos="-0.002 0 -0.213" via default class="foot" — geometrically consistent with
       the real Go2 foot position, so CHAMP locomotion works without re-tuning. -->
  <compiler angle="radian" meshdir="assets/go2_menagerie" autolimits="true"/>

  <option timestep="0.002" gravity="0 0 -9.81" integrator="implicitfast"
          cone="elliptic" impratio="100"/>

  <statistic center="6 0 0.5" extent="8"/>

  <visual>
    <headlight diffuse="0.6 0.6 0.6" ambient="0.3 0.3 0.3" specular="0 0 0"/>
    <rgba haze="0.15 0.25 0.35 1"/>
    <global azimuth="-130" elevation="-20" offwidth="1920" offheight="1080"/>
    <quality shadowsize="4096" offsamples="8"/>
    <map shadowscale="0.5" shadowclip="1"/>
  </visual>

  <default>
    <default class="go2">
      <geom friction="0.6" margin="0.001" condim="1"/>
      <joint axis="0 1 0" damping="2" armature="0.01" frictionloss="0.2"/>
      <motor ctrlrange="-23.7 23.7"/>
      <default class="abduction">
        <joint axis="1 0 0" range="-1.0472 1.0472"/>
      </default>
      <default class="hip">
        <default class="front_hip">
          <joint range="-1.5708 3.4907"/>
        </default>
        <default class="back_hip">
          <joint range="-0.5236 4.5379"/>
        </default>
      </default>
      <default class="knee">
        <joint range="-2.7227 -0.83776"/>
        <motor ctrlrange="-45.43 45.43"/>
      </default>
      <default class="visual">
        <geom type="mesh" contype="0" conaffinity="0" group="2"/>
      </default>
      <default class="collision">
        <geom group="3"/>
        <default class="foot">
          <geom size="0.022" pos="-0.002 0 -0.213" priority="1"
                solimp="0.015 1 0.022" condim="6"
                friction="0.8 0.02 0.01"/>
        </default>
      </default>
    </default>
    <default class="world">
      <geom contype="1" conaffinity="1"/>
    </default>
  </default>

  <asset>
    <!-- Skybox -->
    <texture type="skybox" builtin="gradient" rgb1="0.3 0.5 0.7" rgb2="0 0 0"
             width="512" height="3072"/>

    <!-- Ground -->
    <texture type="2d" name="groundplane" builtin="checker" mark="edge"
             rgb1="0.2 0.3 0.4" rgb2="0.1 0.2 0.3" markrgb="0.8 0.8 0.8"
             width="300" height="300"/>
    <material name="groundplane" texture="groundplane" texuniform="true"
              texrepeat="5 5" reflectance="0.2"/>

    <!-- Robot materials (Menagerie palette) -->
    <material name="metal" rgba=".9 .95 .95 1"/>
    <material name="black" rgba="0 0 0 1"/>
    <material name="white" rgba="1 1 1 1"/>
    <material name="gray" rgba="0.671705 0.692426 0.774270 1"/>

    <!-- Robot meshes (Menagerie OBJ) -->
    <mesh file="base_0.obj"/>
    <mesh file="base_1.obj"/>
    <mesh file="base_2.obj"/>
    <mesh file="base_3.obj"/>
    <mesh file="base_4.obj"/>
    <mesh file="hip_0.obj"/>
    <mesh file="hip_1.obj"/>
    <mesh file="thigh_0.obj"/>
    <mesh file="thigh_1.obj"/>
    <mesh file="thigh_mirror_0.obj"/>
    <mesh file="thigh_mirror_1.obj"/>
    <mesh file="calf_0.obj"/>
    <mesh file="calf_1.obj"/>
    <mesh file="calf_mirror_0.obj"/>
    <mesh file="calf_mirror_1.obj"/>
    <mesh file="foot.obj"/>

    <!-- World materials -->
    <material name="wall_mat" rgba="0.7 0.7 0.75 1"/>
    <material name="divider_mat" rgba="0.8 0.7 0.6 1"/>
    <material name="green_mat" rgba="0.0 1.0 0.0 1" specular="0.3"/>
    <material name="obstacle_mat" rgba="0.6 0.5 0.4 1"/>
  </asset>

  <worldbody>
    <!-- Lighting -->
    <light pos="6 0 8" dir="0 0 -1" directional="true" diffuse="0.8 0.8 0.8"
           castshadow="true"/>

    <!-- Ground plane -->
    <geom name="ground" type="plane" size="50 50 0.1" material="groundplane"
          class="world"/>

    <!-- === Outer walls === -->
    <geom name="wall_north" type="box" pos="6.0 4.1 0.5"
          size="6.1 0.1 0.5" material="wall_mat" class="world"/>
    <geom name="wall_south" type="box" pos="6.0 -4.1 0.5"
          size="6.1 0.1 0.5" material="wall_mat" class="world"/>
    <geom name="wall_west" type="box" pos="-0.1 0 0.5"
          size="0.1 4.1 0.5" material="wall_mat" class="world"/>
    <geom name="wall_east" type="box" pos="12.1 0 0.5"
          size="0.1 4.1 0.5" material="wall_mat" class="world"/>

    <!-- === Central corridor dividers === -->
    <geom name="divider_h_west" type="box" pos="1.5 0 0.5"
          size="1.5 0.075 0.5" material="divider_mat" class="world"/>
    <geom name="divider_h_east" type="box" pos="8.55 0 0.5"
          size="2.55 0.075 0.5" material="divider_mat" class="world"/>
    <geom name="divider_v_north" type="box" pos="5.5 2.5 0.5"
          size="0.075 1.5 0.5" material="divider_mat" class="world"/>

    <!-- === Green marker cylinders === -->
    <geom name="green_marker_1" type="cylinder" pos="2.5 2.5 0.25"
          size="0.15 0.25" material="green_mat" class="world"/>
    <geom name="green_marker_2" type="cylinder" pos="8.5 2.5 0.25"
          size="0.15 0.25" material="green_mat" class="world"/>
    <geom name="green_marker_3" type="cylinder" pos="7.0 -2.5 0.25"
          size="0.15 0.25" material="green_mat" class="world"/>

    <!-- === Box obstacles === -->
    <geom name="box_obstacle_1" type="box" pos="4.0 -2.0 0.3"
          size="0.3 0.3 0.3" euler="0 0 0.3" material="obstacle_mat" class="world"/>
    <geom name="box_obstacle_2" type="box" pos="10.0 -1.5 0.3"
          size="0.25 0.4 0.3" euler="0 0 0.7" material="obstacle_mat" class="world"/>

    <!-- === Go2 robot (Menagerie body; spawn settled-stance at (4, 0, 0.5)) ===
         CHAMP flow still uses this pose — the stand-up trajectory at kp=100
         handles the drop. RL flow overrides via MUJOCO_INIT_KEYFRAME=home,
         which applies the ``home`` keyframe below (z=0.27, legs settled). -->
    <body name="base_link" pos="4.0 0 0.5" childclass="go2">
      <inertial pos="0.021112 0 -0.005366" quat="-0.000543471 0.713435 -0.00173769 0.700719"
        mass="6.921" diaginertia="0.107027 0.0980771 0.0244531"/>
      <freejoint name="root"/>

      <!-- Base visual meshes -->
      <geom mesh="base_0" material="black" class="visual"/>
      <geom mesh="base_1" material="black" class="visual"/>
      <geom mesh="base_2" material="black" class="visual"/>
      <geom mesh="base_3" material="white" class="visual"/>
      <geom mesh="base_4" material="gray" class="visual"/>
      <!-- Base collisions -->
      <geom name="base_collision" size="0.1881 0.04675 0.057" type="box" class="collision"/>
      <geom name="head_upper_collision" size="0.05 0.045" pos="0.285 0 0.01" type="cylinder" class="collision"/>
      <geom name="head_lower_collision" size="0.047" pos="0.293 0 -0.06" class="collision"/>

      <!-- Body-frame site for ground-truth pose sensors -->
      <site name="base_link_site" pos="0 0 0" size="0.01"/>

      <!-- IMU site -->
      <site name="imu" pos="-0.02557 0 0.04232" size="0.01"/>

      <!-- Livox MID-360 site (matches URDF chain base→imu→livox_mid360_base;
           pos = imu_pos + livox_offset = (-0.02557+0.1870, 0, 0.04232+0.0803)) -->
      <site name="livox_mid360" pos="0.16143 0 0.12262" euler="0 0.2269 0" size="0.01"/>

      <!-- Front camera: mounted at Head_upper (0.285,0,0.01), offset fwd+down,
           pitched 5° down. MuJoCo camera looks along -Z; xyaxes rotates to +X. -->
      <camera name="front_camera" pos="0.30 0 -0.01"
              xyaxes="0 -1 0 0.0872 0 0.9962"
              fovy="80" resolution="1280 720" mode="fixed"/>

      <!-- ====== Front-Left leg ====== -->
      <body name="FL_hip" pos="0.1934 0.0465 0">
        <inertial pos="-0.0054 0.00194 -0.000105" quat="0.497014 0.499245 0.505462 0.498237"
          mass="0.678" diaginertia="0.00088403 0.000596003 0.000479967"/>
        <joint name="FL_hip_joint" class="abduction"/>
        <geom mesh="hip_0" material="metal" class="visual"/>
        <geom mesh="hip_1" material="gray" class="visual"/>
        <geom name="FL_hip_collision" size="0.046 0.02" pos="0 0.08 0" quat="1 1 0 0"
              type="cylinder" class="collision"/>
        <body name="FL_thigh" pos="0 0.0955 0">
          <inertial pos="-0.00374 -0.0223 -0.0327" quat="0.829533 0.0847635 -0.0200632 0.551623"
            mass="1.152" diaginertia="0.00594973 0.00584149 0.000878787"/>
          <joint name="FL_thigh_joint" class="front_hip"/>
          <geom mesh="thigh_0" material="metal" class="visual"/>
          <geom mesh="thigh_1" material="gray" class="visual"/>
          <geom name="FL_thigh_collision" size="0.1065 0.01225 0.017" pos="0 0 -0.1065"
                quat="0.707107 0 0.707107 0" type="box" class="collision"/>
          <body name="FL_calf" pos="0 0 -0.213">
            <inertial pos="0.00629595 -0.000622121 -0.141417"
              quat="0.710672 0.00154099 -0.00450087 0.703508"
              mass="0.241352" diaginertia="0.0014901 0.00146356 5.31397e-05"/>
            <joint name="FL_calf_joint" class="knee"/>
            <geom mesh="calf_0" material="gray" class="visual"/>
            <geom mesh="calf_1" material="black" class="visual"/>
            <geom name="FL_calf_upper_collision" size="0.012 0.06" pos="0.008 0 -0.06"
                  quat="0.994493 0 -0.104807 0" type="cylinder" class="collision"/>
            <geom name="FL_calf_lower_collision" size="0.011 0.0325" pos="0.02 0 -0.148"
                  quat="0.999688 0 0.0249974 0" type="cylinder" class="collision"/>
            <geom pos="0 0 -0.213" mesh="foot" class="visual" material="black"/>
            <geom name="FL" class="foot"/>
            <site name="FL_foot_site" pos="-0.002 0 -0.213" size="0.01"/>
          </body>
        </body>
      </body>

      <!-- ====== Front-Right leg ====== -->
      <body name="FR_hip" pos="0.1934 -0.0465 0">
        <inertial pos="-0.0054 -0.00194 -0.000105" quat="0.498237 0.505462 0.499245 0.497014"
          mass="0.678" diaginertia="0.00088403 0.000596003 0.000479967"/>
        <joint name="FR_hip_joint" class="abduction"/>
        <geom mesh="hip_0" material="metal" class="visual" quat="4.63268e-05 1 0 0"/>
        <geom mesh="hip_1" material="gray" class="visual" quat="4.63268e-05 1 0 0"/>
        <geom name="FR_hip_collision" size="0.046 0.02" pos="0 -0.08 0"
              quat="0.707107 0.707107 0 0" type="cylinder" class="collision"/>
        <body name="FR_thigh" pos="0 -0.0955 0">
          <inertial pos="-0.00374 0.0223 -0.0327" quat="0.551623 -0.0200632 0.0847635 0.829533"
            mass="1.152" diaginertia="0.00594973 0.00584149 0.000878787"/>
          <joint name="FR_thigh_joint" class="front_hip"/>
          <geom mesh="thigh_mirror_0" material="metal" class="visual"/>
          <geom mesh="thigh_mirror_1" material="gray" class="visual"/>
          <geom name="FR_thigh_collision" size="0.1065 0.01225 0.017" pos="0 0 -0.1065"
                quat="0.707107 0 0.707107 0" type="box" class="collision"/>
          <body name="FR_calf" pos="0 0 -0.213">
            <inertial pos="0.00629595 0.000622121 -0.141417"
              quat="0.703508 -0.00450087 0.00154099 0.710672"
              mass="0.241352" diaginertia="0.0014901 0.00146356 5.31397e-05"/>
            <joint name="FR_calf_joint" class="knee"/>
            <geom mesh="calf_mirror_0" material="gray" class="visual"/>
            <geom mesh="calf_mirror_1" material="black" class="visual"/>
            <geom name="FR_calf_upper_collision" size="0.013 0.06" pos="0.01 0 -0.06"
                  quat="0.995004 0 -0.0998334 0" type="cylinder" class="collision"/>
            <geom name="FR_calf_lower_collision" size="0.011 0.0325" pos="0.02 0 -0.148"
                  quat="0.999688 0 0.0249974 0" type="cylinder" class="collision"/>
            <geom pos="0 0 -0.213" mesh="foot" class="visual" material="black"/>
            <geom name="FR" class="foot"/>
            <site name="FR_foot_site" pos="-0.002 0 -0.213" size="0.01"/>
          </body>
        </body>
      </body>

      <!-- ====== Rear-Left leg ====== -->
      <body name="RL_hip" pos="-0.1934 0.0465 0">
        <inertial pos="0.0054 0.00194 -0.000105" quat="0.505462 0.498237 0.497014 0.499245"
          mass="0.678" diaginertia="0.00088403 0.000596003 0.000479967"/>
        <joint name="RL_hip_joint" class="abduction"/>
        <geom mesh="hip_0" material="metal" class="visual" quat="4.63268e-05 0 1 0"/>
        <geom mesh="hip_1" material="gray" class="visual" quat="4.63268e-05 0 1 0"/>
        <geom name="RL_hip_collision" size="0.046 0.02" pos="0 0.08 0"
              quat="0.707107 0.707107 0 0" type="cylinder" class="collision"/>
        <body name="RL_thigh" pos="0 0.0955 0">
          <inertial pos="-0.00374 -0.0223 -0.0327" quat="0.829533 0.0847635 -0.0200632 0.551623"
            mass="1.152" diaginertia="0.00594973 0.00584149 0.000878787"/>
          <joint name="RL_thigh_joint" class="back_hip"/>
          <geom mesh="thigh_0" material="metal" class="visual"/>
          <geom mesh="thigh_1" material="gray" class="visual"/>
          <geom name="RL_thigh_collision" size="0.1065 0.01225 0.017" pos="0 0 -0.1065"
                quat="0.707107 0 0.707107 0" type="box" class="collision"/>
          <body name="RL_calf" pos="0 0 -0.213">
            <inertial pos="0.00629595 -0.000622121 -0.141417"
              quat="0.710672 0.00154099 -0.00450087 0.703508"
              mass="0.241352" diaginertia="0.0014901 0.00146356 5.31397e-05"/>
            <joint name="RL_calf_joint" class="knee"/>
            <geom mesh="calf_0" material="gray" class="visual"/>
            <geom mesh="calf_1" material="black" class="visual"/>
            <geom name="RL_calf_upper_collision" size="0.013 0.06" pos="0.01 0 -0.06"
                  quat="0.995004 0 -0.0998334 0" type="cylinder" class="collision"/>
            <geom name="RL_calf_lower_collision" size="0.011 0.0325" pos="0.02 0 -0.148"
                  quat="0.999688 0 0.0249974 0" type="cylinder" class="collision"/>
            <geom pos="0 0 -0.213" mesh="foot" class="visual" material="black"/>
            <geom name="RL" class="foot"/>
            <site name="RL_foot_site" pos="-0.002 0 -0.213" size="0.01"/>
          </body>
        </body>
      </body>

      <!-- ====== Rear-Right leg ====== -->
      <body name="RR_hip" pos="-0.1934 -0.0465 0">
        <inertial pos="0.0054 -0.00194 -0.000105" quat="0.499245 0.497014 0.498237 0.505462"
          mass="0.678" diaginertia="0.00088403 0.000596003 0.000479967"/>
        <joint name="RR_hip_joint" class="abduction"/>
        <geom mesh="hip_0" material="metal" class="visual"
              quat="2.14617e-09 4.63268e-05 4.63268e-05 -1"/>
        <geom mesh="hip_1" material="gray" class="visual"
              quat="2.14617e-09 4.63268e-05 4.63268e-05 -1"/>
        <geom name="RR_hip_collision" size="0.046 0.02" pos="0 -0.08 0"
              quat="0.707107 0.707107 0 0" type="cylinder" class="collision"/>
        <body name="RR_thigh" pos="0 -0.0955 0">
          <inertial pos="-0.00374 0.0223 -0.0327" quat="0.551623 -0.0200632 0.0847635 0.829533"
            mass="1.152" diaginertia="0.00594973 0.00584149 0.000878787"/>
          <joint name="RR_thigh_joint" class="back_hip"/>
          <geom mesh="thigh_mirror_0" material="metal" class="visual"/>
          <geom mesh="thigh_mirror_1" material="gray" class="visual"/>
          <geom name="RR_thigh_collision" size="0.1065 0.01225 0.017" pos="0 0 -0.1065"
                quat="0.707107 0 0.707107 0" type="box" class="collision"/>
          <body name="RR_calf" pos="0 0 -0.213">
            <inertial pos="0.00629595 0.000622121 -0.141417"
              quat="0.703508 -0.00450087 0.00154099 0.710672"
              mass="0.241352" diaginertia="0.0014901 0.00146356 5.31397e-05"/>
            <joint name="RR_calf_joint" class="knee"/>
            <geom mesh="calf_mirror_0" material="gray" class="visual"/>
            <geom mesh="calf_mirror_1" material="black" class="visual"/>
            <geom name="RR_calf_upper_collision" size="0.013 0.06" pos="0.01 0 -0.06"
                  quat="0.995004 0 -0.0998334 0" type="cylinder" class="collision"/>
            <geom name="RR_calf_lower_collision" size="0.011 0.0325" pos="0.02 0 -0.148"
                  quat="0.999688 0 0.0249974 0" type="cylinder" class="collision"/>
            <geom pos="0 0 -0.213" mesh="foot" class="visual" material="black"/>
            <geom name="RR" class="foot"/>
            <site name="RR_foot_site" pos="-0.002 0 -0.213" size="0.01"/>
          </body>
        </body>
      </body>
    </body>
  </worldbody>

  <!-- Actuators: 12 effort motors (no wheel actuators — pure Go2) -->
  <actuator>
    <motor class="abduction" name="FL_hip" joint="FL_hip_joint"/>
    <motor class="hip" name="FL_thigh" joint="FL_thigh_joint"/>
    <motor class="knee" name="FL_calf" joint="FL_calf_joint"/>
    <motor class="abduction" name="FR_hip" joint="FR_hip_joint"/>
    <motor class="hip" name="FR_thigh" joint="FR_thigh_joint"/>
    <motor class="knee" name="FR_calf" joint="FR_calf_joint"/>
    <motor class="abduction" name="RL_hip" joint="RL_hip_joint"/>
    <motor class="hip" name="RL_thigh" joint="RL_thigh_joint"/>
    <motor class="knee" name="RL_calf" joint="RL_calf_joint"/>
    <motor class="abduction" name="RR_hip" joint="RR_hip_joint"/>
    <motor class="hip" name="RR_thigh" joint="RR_thigh_joint"/>
    <motor class="knee" name="RR_calf" joint="RR_calf_joint"/>
  </actuator>

  <!-- Sensors -->
  <!-- Initial state. When env MUJOCO_INIT_KEYFRAME=home is set (RL-policy
       launch does this), DFKI's mujoco_ros2_control plugin calls
       mj_resetDataKeyframe to apply this qpos on startup. Without it the
       default qpos is 0 for every joint — calves then extend straight down
       through the ground at spawn, triggering an explosive contact that
       flips the body forward. qpos layout:
         [x, y, z, qw, qx, qy, qz,
          FL_hip, FL_thigh, FL_calf, FR_hip, FR_thigh, FR_calf,
          RL_hip, RL_thigh, RL_calf, RR_hip, RR_thigh, RR_calf]
       Leg angles (0, 0.9, -1.8) are Menagerie Go2 home stance — body CoG
       ≈ 0.27 m, feet at ground. -->
  <keyframe>
    <key name="home"
         qpos="4.0 0 0.27 1 0 0 0 0 0.9 -1.8 0 0.9 -1.8 0 0.9 -1.8 0 0.9 -1.8"/>
  </keyframe>

  <sensor>
    <accelerometer name="imu_accel" site="imu"/>
    <gyro name="imu_gyro" site="imu"/>

    <touch name="FL_foot_contact" site="FL_foot_site"/>
    <touch name="FR_foot_contact" site="FR_foot_site"/>
    <touch name="RL_foot_contact" site="RL_foot_site"/>
    <touch name="RR_foot_contact" site="RR_foot_site"/>

    <framepos name="base_pos" objtype="site" objname="base_link_site"/>
    <framequat name="base_quat" objtype="site" objname="base_link_site"/>
    <framelinvel name="base_linvel" objtype="site" objname="base_link_site"/>
    <frameangvel name="base_angvel" objtype="site" objname="base_link_site"/>
  </sensor>
</mujoco>
